/usr/local/lib/python2.7/dist-packages/matplotlib/axes/_axes.py:545: UserWarning: No labelled objects found. Use label='...' kwarg on individual plots.
  warnings.warn("No labelled objects found. "
WARNING:root:Too few points to create valid contours
ClusterEmcee2_linear_mu_2step.py:165: RuntimeWarning: invalid value encountered in log10
  mag = 22.5-2.5*np.log10(delta_f*mu['r'] + mu['r'])
ClusterEmcee2_linear_mu_2step.py:285: RuntimeWarning: invalid value encountered in greater
  mag_crit = (mags > 0) & (mags != 22.5) & (mags != np.inf) & ~np.isnan(mags)
('200', '300', 'normal')
Running object 200
0.0
{'i': 82, 'r': 33, 'z': 167}
{'i': 1.0509269, 'r': 0.35775697, 'z': 1.8077606, 'g': 0.0}
Variable??
0
Non-Variable source in g
Variable??
1.5468368749110353
Non-Variable source in r
Variable??
1.931870720940812
Non-Variable source in i
Variable??
2.6814749753254232
Non-Variable source in z
Slope:       [1, 1, 1, 0.13928716812404707]
Slope Error: [0.0, 0, 0.08565346023409161, 0.06554329956564972]
intercepts:  [0, 0, 0.004242035107161035, -0.0005812390156090252]
Int Error:   [0.0, 0, 0.011101615595999141, 0.008420494377726365]
StDev:       [0.0, 0.045299154, 0.0820365, 0.1637107]
('ROW:', 200, 'Tau:', '5.650384907390023e-05', 'V:', '0.5477829034222849')
Traceback (most recent call last):
  File "ClusterEmcee2_linear_mu_2step.py", line 509, in <module>
    perform_emcee_step2(time, flux_mod, err_mod, dMu_dict, scale_dict, color_sort_ones, ROW, mu)
  File "ClusterEmcee2_linear_mu_2step.py", line 339, in perform_emcee_step2
    sausageplot_step2(max_theta[0], time, flux, max_theta[1], 5, err**2, dMu_dict, scale_dict, color_sort_ones, ROW, fig)
  File "ClusterEmcee2_linear_mu_2step.py", line 178, in sausageplot_step2
    ax4.legend()
  File "/usr/local/lib/python2.7/dist-packages/matplotlib/axes/_axes.py", line 564, in legend
    self.legend_ = mlegend.Legend(self, handles, labels, **kwargs)
  File "/usr/local/lib/python2.7/dist-packages/matplotlib/legend.py", line 386, in __init__
    self._init_legend_box(handles, labels, markerfirst)
  File "/usr/local/lib/python2.7/dist-packages/matplotlib/legend.py", line 655, in _init_legend_box
    fontsize, handlebox))
  File "/usr/local/lib/python2.7/dist-packages/matplotlib/legend_handler.py", line 119, in legend_artist
    fontsize, handlebox.get_transform())
  File "/usr/local/lib/python2.7/dist-packages/matplotlib/legend_handler.py", line 476, in create_artists
    self.update_prop(coll, barlinecols[0], legend)
IndexError: tuple index out of range
